[I 2025-05-08 18:33:44.587 ServerApp] jupyter_lsp | extension was successfully linked.
[I 2025-05-08 18:33:44.590 ServerApp] jupyter_server_terminals | extension was successfully linked.
[I 2025-05-08 18:33:44.593 ServerApp] jupyterlab | extension was successfully linked.
[W 2025-05-08 18:33:44.595 JupyterNotebookApp] 'allow_origin' has moved from NotebookApp to ServerApp. This config will be passed to ServerApp. Be sure to update your config before our next release.
[W 2025-05-08 18:33:44.595 JupyterNotebookApp] 'ip' has moved from NotebookApp to ServerApp. This config will be passed to ServerApp. Be sure to update your config before our next release.
[I 2025-05-08 18:33:44.597 ServerApp] notebook | extension was successfully linked.
[I 2025-05-08 18:33:44.751 ServerApp] notebook_shim | extension was successfully linked.
[I 2025-05-08 18:33:44.763 ServerApp] notebook_shim | extension was successfully loaded.
[I 2025-05-08 18:33:44.765 ServerApp] jupyter_lsp | extension was successfully loaded.
[I 2025-05-08 18:33:44.766 ServerApp] jupyter_server_terminals | extension was successfully loaded.
[I 2025-05-08 18:33:44.767 LabApp] JupyterLab extension loaded from /opt/notebooks/final_project/.venv/lib/python3.12/site-packages/jupyterlab
[I 2025-05-08 18:33:44.767 LabApp] JupyterLab application directory is /opt/notebooks/final_project/.venv/share/jupyter/lab
[I 2025-05-08 18:33:44.768 LabApp] Extension Manager is 'pypi'.
[I 2025-05-08 18:33:44.805 ServerApp] jupyterlab | extension was successfully loaded.
[I 2025-05-08 18:33:44.808 ServerApp] notebook | extension was successfully loaded.
[I 2025-05-08 18:33:44.808 ServerApp] Serving notebooks from local directory: /opt/notebooks/final_project
[I 2025-05-08 18:33:44.808 ServerApp] Jupyter Server 2.15.0 is running at:
[I 2025-05-08 18:33:44.808 ServerApp] http://ip-172-31-38-211:8888/lab
[I 2025-05-08 18:33:44.808 ServerApp]     http://127.0.0.1:8888/lab
[I 2025-05-08 18:33:44.808 ServerApp] Use Control-C to stop this server and shut down all kernels (twice to skip confirmation).
[I 2025-05-08 18:33:44.822 ServerApp] Skipped non-installed server(s): bash-language-server, dockerfile-language-server-nodejs, javascript-typescript-langserver, jedi-language-server, julia-language-server, pyright, python-language-server, python-lsp-server, r-languageserver, sql-language-server, texlab, typescript-language-server, unified-language-server, vscode-css-languageserver-bin, vscode-html-languageserver-bin, vscode-json-languageserver-bin, yaml-language-server
[W 2025-05-08 18:33:55.636 ServerApp] 404 GET /robots.txt?485202 (@85.50.127.70) 10.03ms referer=None
[W 2025-05-08 18:33:56.696 LabApp] Could not determine jupyterlab build status without nodejs
[W 2025-05-08 18:33:58.162 ServerApp] 404 GET /api/contents/final_project?content=0&hash=0&1746729238040 (8143833b376641c1802f0600d788494f@85.50.127.70) 0.87ms referer=http://108.128.212.205:8888/lab/tree/final_project
[W 2025-05-08 18:33:58.162 ServerApp] 404 GET /api/contents/final_project?content=0&hash=0&1746729238040 (85.50.127.70): No such file or directory: final_project
[W 2025-05-08 18:34:04.475 ServerApp] Notebook Final_project.ipynb is not trusted
[I 2025-05-08 18:34:04.950 ServerApp] Kernel started: c1d42182-d42d-4f04-9f08-43dce804ac64
[I 2025-05-08 18:34:05.364 ServerApp] Connecting to kernel c1d42182-d42d-4f04-9f08-43dce804ac64.
[I 2025-05-08 18:34:05.471 ServerApp] Connecting to kernel c1d42182-d42d-4f04-9f08-43dce804ac64.
[I 2025-05-08 18:34:05.577 ServerApp] Connecting to kernel c1d42182-d42d-4f04-9f08-43dce804ac64.
[I 2025-05-08 18:36:04.613 ServerApp] Saving file at /Final_project.ipynb
[W 2025-05-08 18:36:04.614 ServerApp] Notebook Final_project.ipynb is not trusted
[W 2025-05-08 18:43:36.455 ServerApp] 404 GET /api/contents/.venv/lib/python3.12/site-packages/cobra/io/sbml.py?content=0&hash=0&1746729816327 (8143833b376641c1802f0600d788494f@85.50.127.70) 0.70ms referer=http://108.128.212.205:8888/lab/tree/Final_project.ipynb
[I 2025-05-08 18:43:36.456 ServerApp] Refusing to serve hidden file or directory '/opt/notebooks/final_project/.venv/lib/python3.12/site-packages/cobra/io/sbml.py', via 404 Error
[E 2025-05-08 18:43:36.456 ServerApp] Uncaught exception GET /api/contents/.venv/lib/python3.12/site-packages/cobra/io/sbml.py?content=0&hash=0&1746729816327 (85.50.127.70)
    HTTPServerRequest(protocol='http', host='108.128.212.205:8888', method='GET', uri='/api/contents/.venv/lib/python3.12/site-packages/cobra/io/sbml.py?content=0&hash=0&1746729816327', version='HTTP/1.1', remote_ip='85.50.127.70')
    Traceback (most recent call last):
      File "/opt/notebooks/final_project/.venv/lib/python3.12/site-packages/jupyter_server/services/contents/handlers.py", line 156, in get
        model = await ensure_async(
                ^^^^^^^^^^^^^^^^^^^
      File "/opt/notebooks/final_project/.venv/lib/python3.12/site-packages/jupyter_core/utils/__init__.py", line 198, in ensure_async
        result = await obj
                 ^^^^^^^^^
      File "/opt/notebooks/final_project/.venv/lib/python3.12/site-packages/jupyter_server/services/contents/filemanager.py", line 926, in get
        model = await self._file_model(
                ^^^^^^^^^^^^^^^^^^^^^^^
      File "/opt/notebooks/final_project/.venv/lib/python3.12/site-packages/jupyter_server/services/contents/filemanager.py", line 827, in _file_model
        model = self._base_model(path)
                ^^^^^^^^^^^^^^^^^^^^^^
      File "/opt/notebooks/final_project/.venv/lib/python3.12/site-packages/jupyter_server/services/contents/filemanager.py", line 237, in _base_model
        raise web.HTTPError(404, four_o_four)
    tornado.web.HTTPError: HTTP 404: Not Found (file or directory does not exist: '.venv/lib/python3.12/site-packages/cobra/io/sbml.py')
    
    During handling of the above exception, another exception occurred:
    
    Traceback (most recent call last):
      File "/opt/notebooks/final_project/.venv/lib/python3.12/site-packages/tornado/web.py", line 1790, in _execute
        result = await result
                 ^^^^^^^^^^^^
      File "/opt/notebooks/final_project/.venv/lib/python3.12/site-packages/jupyter_server/auth/decorator.py", line 73, in inner
        return await out
               ^^^^^^^^^
      File "/opt/notebooks/final_project/.venv/lib/python3.12/site-packages/jupyter_server/services/contents/handlers.py", line 182, in get
        await self._finish_error(
      File "/opt/notebooks/final_project/.venv/lib/python3.12/site-packages/jupyter_server/services/contents/handlers.py", line 114, in _finish_error
        self.write(message)
      File "/opt/notebooks/final_project/.venv/lib/python3.12/site-packages/tornado/web.py", line 914, in write
        raise RuntimeError("Cannot write() after finish()")
    RuntimeError: Cannot write() after finish()
[W 2025-05-08 18:43:36.458 ServerApp] 404 GET /api/contents/.venv/lib/python3.12/site-packages/cobra/io/sbml.py?content=0&hash=0&1746729816327 (8143833b376641c1802f0600d788494f@85.50.127.70) 0.39ms referer=http://108.128.212.205:8888/lab/tree/Final_project.ipynb
[I 2025-05-08 18:43:36.458 ServerApp] Refusing to serve hidden file or directory '/opt/notebooks/final_project/.venv/lib/python3.12/site-packages/cobra/io/sbml.py', via 404 Error
[E 2025-05-08 18:43:36.458 ServerApp] Uncaught exception GET /api/contents/.venv/lib/python3.12/site-packages/cobra/io/sbml.py?content=0&hash=0&1746729816327 (85.50.127.70)
    HTTPServerRequest(protocol='http', host='108.128.212.205:8888', method='GET', uri='/api/contents/.venv/lib/python3.12/site-packages/cobra/io/sbml.py?content=0&hash=0&1746729816327', version='HTTP/1.1', remote_ip='85.50.127.70')
    Traceback (most recent call last):
      File "/opt/notebooks/final_project/.venv/lib/python3.12/site-packages/jupyter_server/services/contents/handlers.py", line 156, in get
        model = await ensure_async(
                ^^^^^^^^^^^^^^^^^^^
      File "/opt/notebooks/final_project/.venv/lib/python3.12/site-packages/jupyter_core/utils/__init__.py", line 198, in ensure_async
        result = await obj
                 ^^^^^^^^^
      File "/opt/notebooks/final_project/.venv/lib/python3.12/site-packages/jupyter_server/services/contents/filemanager.py", line 926, in get
        model = await self._file_model(
                ^^^^^^^^^^^^^^^^^^^^^^^
      File "/opt/notebooks/final_project/.venv/lib/python3.12/site-packages/jupyter_server/services/contents/filemanager.py", line 827, in _file_model
        model = self._base_model(path)
                ^^^^^^^^^^^^^^^^^^^^^^
      File "/opt/notebooks/final_project/.venv/lib/python3.12/site-packages/jupyter_server/services/contents/filemanager.py", line 237, in _base_model
        raise web.HTTPError(404, four_o_four)
    tornado.web.HTTPError: HTTP 404: Not Found (file or directory does not exist: '.venv/lib/python3.12/site-packages/cobra/io/sbml.py')
    
    During handling of the above exception, another exception occurred:
    
    Traceback (most recent call last):
      File "/opt/notebooks/final_project/.venv/lib/python3.12/site-packages/tornado/web.py", line 1790, in _execute
        result = await result
                 ^^^^^^^^^^^^
      File "/opt/notebooks/final_project/.venv/lib/python3.12/site-packages/jupyter_server/auth/decorator.py", line 73, in inner
        return await out
               ^^^^^^^^^
      File "/opt/notebooks/final_project/.venv/lib/python3.12/site-packages/jupyter_server/services/contents/handlers.py", line 182, in get
        await self._finish_error(
      File "/opt/notebooks/final_project/.venv/lib/python3.12/site-packages/jupyter_server/services/contents/handlers.py", line 114, in _finish_error
        self.write(message)
      File "/opt/notebooks/final_project/.venv/lib/python3.12/site-packages/tornado/web.py", line 914, in write
        raise RuntimeError("Cannot write() after finish()")
    RuntimeError: Cannot write() after finish()
[W 2025-05-08 18:43:36.466 ServerApp] 404 GET /api/contents/.venv/lib/python3.12/site-packages/cobra/io/sbml.py?content=0&hash=0&1746729816327 (8143833b376641c1802f0600d788494f@85.50.127.70) 0.36ms referer=http://108.128.212.205:8888/lab/tree/Final_project.ipynb
[I 2025-05-08 18:43:36.466 ServerApp] Refusing to serve hidden file or directory '/opt/notebooks/final_project/.venv/lib/python3.12/site-packages/cobra/io/sbml.py', via 404 Error
[E 2025-05-08 18:43:36.466 ServerApp] Uncaught exception GET /api/contents/.venv/lib/python3.12/site-packages/cobra/io/sbml.py?content=0&hash=0&1746729816327 (85.50.127.70)
    HTTPServerRequest(protocol='http', host='108.128.212.205:8888', method='GET', uri='/api/contents/.venv/lib/python3.12/site-packages/cobra/io/sbml.py?content=0&hash=0&1746729816327', version='HTTP/1.1', remote_ip='85.50.127.70')
    Traceback (most recent call last):
      File "/opt/notebooks/final_project/.venv/lib/python3.12/site-packages/jupyter_server/services/contents/handlers.py", line 156, in get
        model = await ensure_async(
                ^^^^^^^^^^^^^^^^^^^
      File "/opt/notebooks/final_project/.venv/lib/python3.12/site-packages/jupyter_core/utils/__init__.py", line 198, in ensure_async
        result = await obj
                 ^^^^^^^^^
      File "/opt/notebooks/final_project/.venv/lib/python3.12/site-packages/jupyter_server/services/contents/filemanager.py", line 926, in get
        model = await self._file_model(
                ^^^^^^^^^^^^^^^^^^^^^^^
      File "/opt/notebooks/final_project/.venv/lib/python3.12/site-packages/jupyter_server/services/contents/filemanager.py", line 827, in _file_model
        model = self._base_model(path)
                ^^^^^^^^^^^^^^^^^^^^^^
      File "/opt/notebooks/final_project/.venv/lib/python3.12/site-packages/jupyter_server/services/contents/filemanager.py", line 237, in _base_model
        raise web.HTTPError(404, four_o_four)
    tornado.web.HTTPError: HTTP 404: Not Found (file or directory does not exist: '.venv/lib/python3.12/site-packages/cobra/io/sbml.py')
    
    During handling of the above exception, another exception occurred:
    
    Traceback (most recent call last):
      File "/opt/notebooks/final_project/.venv/lib/python3.12/site-packages/tornado/web.py", line 1790, in _execute
        result = await result
                 ^^^^^^^^^^^^
      File "/opt/notebooks/final_project/.venv/lib/python3.12/site-packages/jupyter_server/auth/decorator.py", line 73, in inner
        return await out
               ^^^^^^^^^
      File "/opt/notebooks/final_project/.venv/lib/python3.12/site-packages/jupyter_server/services/contents/handlers.py", line 182, in get
        await self._finish_error(
      File "/opt/notebooks/final_project/.venv/lib/python3.12/site-packages/jupyter_server/services/contents/handlers.py", line 114, in _finish_error
        self.write(message)
      File "/opt/notebooks/final_project/.venv/lib/python3.12/site-packages/tornado/web.py", line 914, in write
        raise RuntimeError("Cannot write() after finish()")
    RuntimeError: Cannot write() after finish()
[I 2025-05-08 18:44:05.315 ServerApp] Saving file at /Final_project.ipynb
[I 2025-05-08 18:46:05.488 ServerApp] Saving file at /Final_project.ipynb
[I 2025-05-08 18:48:05.657 ServerApp] Saving file at /Final_project.ipynb
[I 2025-05-08 18:50:05.821 ServerApp] Saving file at /Final_project.ipynb
[I 2025-05-08 18:51:30.706 ServerApp] 302 GET / (@79.116.128.16) 0.49ms
[I 2025-05-08 18:51:30.761 LabApp] 302 GET /lab? (@79.116.128.16) 0.45ms
[I 2025-05-08 18:52:05.997 ServerApp] Saving file at /Final_project.ipynb
[I 2025-05-08 18:53:53.515 ServerApp] Kernel interrupted: c1d42182-d42d-4f04-9f08-43dce804ac64
[W 2025-05-08 18:53:54.183 ServerApp] 404 GET /api/contents/.venv/lib/python3.12/site-packages/Bio/Align/__init__.py?content=0&hash=0&1746730434041 (8143833b376641c1802f0600d788494f@85.50.127.70) 0.89ms referer=http://108.128.212.205:8888/lab/tree/Final_project.ipynb
[I 2025-05-08 18:53:54.183 ServerApp] Refusing to serve hidden file or directory '/opt/notebooks/final_project/.venv/lib/python3.12/site-packages/Bio/Align/__init__.py', via 404 Error
[E 2025-05-08 18:53:54.183 ServerApp] Uncaught exception GET /api/contents/.venv/lib/python3.12/site-packages/Bio/Align/__init__.py?content=0&hash=0&1746730434041 (85.50.127.70)
    HTTPServerRequest(protocol='http', host='108.128.212.205:8888', method='GET', uri='/api/contents/.venv/lib/python3.12/site-packages/Bio/Align/__init__.py?content=0&hash=0&1746730434041', version='HTTP/1.1', remote_ip='85.50.127.70')
    Traceback (most recent call last):
      File "/opt/notebooks/final_project/.venv/lib/python3.12/site-packages/jupyter_server/services/contents/handlers.py", line 156, in get
        model = await ensure_async(
                ^^^^^^^^^^^^^^^^^^^
      File "/opt/notebooks/final_project/.venv/lib/python3.12/site-packages/jupyter_core/utils/__init__.py", line 198, in ensure_async
        result = await obj
                 ^^^^^^^^^
      File "/opt/notebooks/final_project/.venv/lib/python3.12/site-packages/jupyter_server/services/contents/filemanager.py", line 926, in get
        model = await self._file_model(
                ^^^^^^^^^^^^^^^^^^^^^^^
      File "/opt/notebooks/final_project/.venv/lib/python3.12/site-packages/jupyter_server/services/contents/filemanager.py", line 827, in _file_model
        model = self._base_model(path)
                ^^^^^^^^^^^^^^^^^^^^^^
      File "/opt/notebooks/final_project/.venv/lib/python3.12/site-packages/jupyter_server/services/contents/filemanager.py", line 237, in _base_model
        raise web.HTTPError(404, four_o_four)
    tornado.web.HTTPError: HTTP 404: Not Found (file or directory does not exist: '.venv/lib/python3.12/site-packages/Bio/Align/__init__.py')
    
    During handling of the above exception, another exception occurred:
    
    Traceback (most recent call last):
      File "/opt/notebooks/final_project/.venv/lib/python3.12/site-packages/tornado/web.py", line 1790, in _execute
        result = await result
                 ^^^^^^^^^^^^
      File "/opt/notebooks/final_project/.venv/lib/python3.12/site-packages/jupyter_server/auth/decorator.py", line 73, in inner
        return await out
               ^^^^^^^^^
      File "/opt/notebooks/final_project/.venv/lib/python3.12/site-packages/jupyter_server/services/contents/handlers.py", line 182, in get
        await self._finish_error(
      File "/opt/notebooks/final_project/.venv/lib/python3.12/site-packages/jupyter_server/services/contents/handlers.py", line 114, in _finish_error
        self.write(message)
      File "/opt/notebooks/final_project/.venv/lib/python3.12/site-packages/tornado/web.py", line 914, in write
        raise RuntimeError("Cannot write() after finish()")
    RuntimeError: Cannot write() after finish()
[I 2025-05-08 18:54:06.186 ServerApp] Saving file at /Final_project.ipynb
[I 2025-05-08 18:58:06.373 ServerApp] Saving file at /Final_project.ipynb
[I 2025-05-08 19:00:06.553 ServerApp] Saving file at /Final_project.ipynb
[I 2025-05-08 19:02:06.719 ServerApp] Saving file at /Final_project.ipynb
[I 2025-05-08 19:10:06.898 ServerApp] Saving file at /Final_project.ipynb
[I 2025-05-08 19:12:07.417 ServerApp] Saving file at /Final_project.ipynb
[I 2025-05-08 19:14:07.615 ServerApp] Saving file at /Final_project.ipynb
[I 2025-05-08 19:16:07.807 ServerApp] Saving file at /Final_project.ipynb
[I 2025-05-08 19:18:07.999 ServerApp] Saving file at /Final_project.ipynb
[I 2025-05-08 19:26:09.417 ServerApp] Saving file at /Final_project.ipynb
[I 2025-05-08 19:27:58.810 ServerApp] Kernel interrupted: c1d42182-d42d-4f04-9f08-43dce804ac64
[W 2025-05-08 19:27:58.911 ServerApp] 404 GET /api/contents/.venv/lib/python3.12/site-packages/Bio/Align/__init__.py?content=0&hash=0&1746732478736 (8143833b376641c1802f0600d788494f@85.50.127.70) 0.90ms referer=http://108.128.212.205:8888/lab/tree/Final_project.ipynb
[I 2025-05-08 19:27:58.911 ServerApp] Refusing to serve hidden file or directory '/opt/notebooks/final_project/.venv/lib/python3.12/site-packages/Bio/Align/__init__.py', via 404 Error
[E 2025-05-08 19:27:58.911 ServerApp] Uncaught exception GET /api/contents/.venv/lib/python3.12/site-packages/Bio/Align/__init__.py?content=0&hash=0&1746732478736 (85.50.127.70)
    HTTPServerRequest(protocol='http', host='108.128.212.205:8888', method='GET', uri='/api/contents/.venv/lib/python3.12/site-packages/Bio/Align/__init__.py?content=0&hash=0&1746732478736', version='HTTP/1.1', remote_ip='85.50.127.70')
    Traceback (most recent call last):
      File "/opt/notebooks/final_project/.venv/lib/python3.12/site-packages/jupyter_server/services/contents/handlers.py", line 156, in get
        model = await ensure_async(
                ^^^^^^^^^^^^^^^^^^^
      File "/opt/notebooks/final_project/.venv/lib/python3.12/site-packages/jupyter_core/utils/__init__.py", line 198, in ensure_async
        result = await obj
                 ^^^^^^^^^
      File "/opt/notebooks/final_project/.venv/lib/python3.12/site-packages/jupyter_server/services/contents/filemanager.py", line 926, in get
        model = await self._file_model(
                ^^^^^^^^^^^^^^^^^^^^^^^
      File "/opt/notebooks/final_project/.venv/lib/python3.12/site-packages/jupyter_server/services/contents/filemanager.py", line 827, in _file_model
        model = self._base_model(path)
                ^^^^^^^^^^^^^^^^^^^^^^
      File "/opt/notebooks/final_project/.venv/lib/python3.12/site-packages/jupyter_server/services/contents/filemanager.py", line 237, in _base_model
        raise web.HTTPError(404, four_o_four)
    tornado.web.HTTPError: HTTP 404: Not Found (file or directory does not exist: '.venv/lib/python3.12/site-packages/Bio/Align/__init__.py')
    
    During handling of the above exception, another exception occurred:
    
    Traceback (most recent call last):
      File "/opt/notebooks/final_project/.venv/lib/python3.12/site-packages/tornado/web.py", line 1790, in _execute
        result = await result
                 ^^^^^^^^^^^^
      File "/opt/notebooks/final_project/.venv/lib/python3.12/site-packages/jupyter_server/auth/decorator.py", line 73, in inner
        return await out
               ^^^^^^^^^
      File "/opt/notebooks/final_project/.venv/lib/python3.12/site-packages/jupyter_server/services/contents/handlers.py", line 182, in get
        await self._finish_error(
      File "/opt/notebooks/final_project/.venv/lib/python3.12/site-packages/jupyter_server/services/contents/handlers.py", line 114, in _finish_error
        self.write(message)
      File "/opt/notebooks/final_project/.venv/lib/python3.12/site-packages/tornado/web.py", line 914, in write
        raise RuntimeError("Cannot write() after finish()")
    RuntimeError: Cannot write() after finish()
[I 2025-05-08 19:28:09.596 ServerApp] Saving file at /Final_project.ipynb
[I 2025-05-08 19:29:04.891 ServerApp] Kernel interrupted: c1d42182-d42d-4f04-9f08-43dce804ac64
[W 2025-05-08 19:29:04.985 ServerApp] 404 GET /api/contents/.venv/lib/python3.12/site-packages/Bio/Align/__init__.py?content=0&hash=0&1746732544813 (8143833b376641c1802f0600d788494f@85.50.127.70) 0.61ms referer=http://108.128.212.205:8888/lab/tree/Final_project.ipynb
[I 2025-05-08 19:29:04.985 ServerApp] Refusing to serve hidden file or directory '/opt/notebooks/final_project/.venv/lib/python3.12/site-packages/Bio/Align/__init__.py', via 404 Error
[E 2025-05-08 19:29:04.985 ServerApp] Uncaught exception GET /api/contents/.venv/lib/python3.12/site-packages/Bio/Align/__init__.py?content=0&hash=0&1746732544813 (85.50.127.70)
    HTTPServerRequest(protocol='http', host='108.128.212.205:8888', method='GET', uri='/api/contents/.venv/lib/python3.12/site-packages/Bio/Align/__init__.py?content=0&hash=0&1746732544813', version='HTTP/1.1', remote_ip='85.50.127.70')
    Traceback (most recent call last):
      File "/opt/notebooks/final_project/.venv/lib/python3.12/site-packages/jupyter_server/services/contents/handlers.py", line 156, in get
        model = await ensure_async(
                ^^^^^^^^^^^^^^^^^^^
      File "/opt/notebooks/final_project/.venv/lib/python3.12/site-packages/jupyter_core/utils/__init__.py", line 198, in ensure_async
        result = await obj
                 ^^^^^^^^^
      File "/opt/notebooks/final_project/.venv/lib/python3.12/site-packages/jupyter_server/services/contents/filemanager.py", line 926, in get
        model = await self._file_model(
                ^^^^^^^^^^^^^^^^^^^^^^^
      File "/opt/notebooks/final_project/.venv/lib/python3.12/site-packages/jupyter_server/services/contents/filemanager.py", line 827, in _file_model
        model = self._base_model(path)
                ^^^^^^^^^^^^^^^^^^^^^^
      File "/opt/notebooks/final_project/.venv/lib/python3.12/site-packages/jupyter_server/services/contents/filemanager.py", line 237, in _base_model
        raise web.HTTPError(404, four_o_four)
    tornado.web.HTTPError: HTTP 404: Not Found (file or directory does not exist: '.venv/lib/python3.12/site-packages/Bio/Align/__init__.py')
    
    During handling of the above exception, another exception occurred:
    
    Traceback (most recent call last):
      File "/opt/notebooks/final_project/.venv/lib/python3.12/site-packages/tornado/web.py", line 1790, in _execute
        result = await result
                 ^^^^^^^^^^^^
      File "/opt/notebooks/final_project/.venv/lib/python3.12/site-packages/jupyter_server/auth/decorator.py", line 73, in inner
        return await out
               ^^^^^^^^^
      File "/opt/notebooks/final_project/.venv/lib/python3.12/site-packages/jupyter_server/services/contents/handlers.py", line 182, in get
        await self._finish_error(
      File "/opt/notebooks/final_project/.venv/lib/python3.12/site-packages/jupyter_server/services/contents/handlers.py", line 114, in _finish_error
        self.write(message)
      File "/opt/notebooks/final_project/.venv/lib/python3.12/site-packages/tornado/web.py", line 914, in write
        raise RuntimeError("Cannot write() after finish()")
    RuntimeError: Cannot write() after finish()
[W 2025-05-08 19:29:46.565 ServerApp] 404 GET /api/contents/.venv/lib/python3.12/site-packages/Bio/pairwise2.py?content=0&hash=0&1746732586371 (8143833b376641c1802f0600d788494f@85.50.127.70) 0.86ms referer=http://108.128.212.205:8888/lab/tree/Final_project.ipynb
[I 2025-05-08 19:29:46.565 ServerApp] Refusing to serve hidden file or directory '/opt/notebooks/final_project/.venv/lib/python3.12/site-packages/Bio/pairwise2.py', via 404 Error
[E 2025-05-08 19:29:46.565 ServerApp] Uncaught exception GET /api/contents/.venv/lib/python3.12/site-packages/Bio/pairwise2.py?content=0&hash=0&1746732586371 (85.50.127.70)
    HTTPServerRequest(protocol='http', host='108.128.212.205:8888', method='GET', uri='/api/contents/.venv/lib/python3.12/site-packages/Bio/pairwise2.py?content=0&hash=0&1746732586371', version='HTTP/1.1', remote_ip='85.50.127.70')
    Traceback (most recent call last):
      File "/opt/notebooks/final_project/.venv/lib/python3.12/site-packages/jupyter_server/services/contents/handlers.py", line 156, in get
        model = await ensure_async(
                ^^^^^^^^^^^^^^^^^^^
      File "/opt/notebooks/final_project/.venv/lib/python3.12/site-packages/jupyter_core/utils/__init__.py", line 198, in ensure_async
        result = await obj
                 ^^^^^^^^^
      File "/opt/notebooks/final_project/.venv/lib/python3.12/site-packages/jupyter_server/services/contents/filemanager.py", line 926, in get
        model = await self._file_model(
                ^^^^^^^^^^^^^^^^^^^^^^^
      File "/opt/notebooks/final_project/.venv/lib/python3.12/site-packages/jupyter_server/services/contents/filemanager.py", line 827, in _file_model
        model = self._base_model(path)
                ^^^^^^^^^^^^^^^^^^^^^^
      File "/opt/notebooks/final_project/.venv/lib/python3.12/site-packages/jupyter_server/services/contents/filemanager.py", line 237, in _base_model
        raise web.HTTPError(404, four_o_four)
    tornado.web.HTTPError: HTTP 404: Not Found (file or directory does not exist: '.venv/lib/python3.12/site-packages/Bio/pairwise2.py')
    
    During handling of the above exception, another exception occurred:
    
    Traceback (most recent call last):
      File "/opt/notebooks/final_project/.venv/lib/python3.12/site-packages/tornado/web.py", line 1790, in _execute
        result = await result
                 ^^^^^^^^^^^^
      File "/opt/notebooks/final_project/.venv/lib/python3.12/site-packages/jupyter_server/auth/decorator.py", line 73, in inner
        return await out
               ^^^^^^^^^
      File "/opt/notebooks/final_project/.venv/lib/python3.12/site-packages/jupyter_server/services/contents/handlers.py", line 182, in get
        await self._finish_error(
      File "/opt/notebooks/final_project/.venv/lib/python3.12/site-packages/jupyter_server/services/contents/handlers.py", line 114, in _finish_error
        self.write(message)
      File "/opt/notebooks/final_project/.venv/lib/python3.12/site-packages/tornado/web.py", line 914, in write
        raise RuntimeError("Cannot write() after finish()")
    RuntimeError: Cannot write() after finish()
[I 2025-05-08 19:30:09.767 ServerApp] Saving file at /Final_project.ipynb
[I 2025-05-08 19:31:56.982 ServerApp] Kernel interrupted: c1d42182-d42d-4f04-9f08-43dce804ac64
[W 2025-05-08 19:31:57.111 ServerApp] 404 GET /api/contents/.venv/lib/python3.12/site-packages/Bio/pairwise2.py?content=0&hash=0&1746732716942 (8143833b376641c1802f0600d788494f@85.50.127.70) 0.49ms referer=http://108.128.212.205:8888/lab/tree/Final_project.ipynb
[I 2025-05-08 19:31:57.111 ServerApp] Refusing to serve hidden file or directory '/opt/notebooks/final_project/.venv/lib/python3.12/site-packages/Bio/pairwise2.py', via 404 Error
[E 2025-05-08 19:31:57.111 ServerApp] Uncaught exception GET /api/contents/.venv/lib/python3.12/site-packages/Bio/pairwise2.py?content=0&hash=0&1746732716942 (85.50.127.70)
    HTTPServerRequest(protocol='http', host='108.128.212.205:8888', method='GET', uri='/api/contents/.venv/lib/python3.12/site-packages/Bio/pairwise2.py?content=0&hash=0&1746732716942', version='HTTP/1.1', remote_ip='85.50.127.70')
    Traceback (most recent call last):
      File "/opt/notebooks/final_project/.venv/lib/python3.12/site-packages/jupyter_server/services/contents/handlers.py", line 156, in get
        model = await ensure_async(
                ^^^^^^^^^^^^^^^^^^^
      File "/opt/notebooks/final_project/.venv/lib/python3.12/site-packages/jupyter_core/utils/__init__.py", line 198, in ensure_async
        result = await obj
                 ^^^^^^^^^
      File "/opt/notebooks/final_project/.venv/lib/python3.12/site-packages/jupyter_server/services/contents/filemanager.py", line 926, in get
        model = await self._file_model(
                ^^^^^^^^^^^^^^^^^^^^^^^
      File "/opt/notebooks/final_project/.venv/lib/python3.12/site-packages/jupyter_server/services/contents/filemanager.py", line 827, in _file_model
        model = self._base_model(path)
                ^^^^^^^^^^^^^^^^^^^^^^
      File "/opt/notebooks/final_project/.venv/lib/python3.12/site-packages/jupyter_server/services/contents/filemanager.py", line 237, in _base_model
        raise web.HTTPError(404, four_o_four)
    tornado.web.HTTPError: HTTP 404: Not Found (file or directory does not exist: '.venv/lib/python3.12/site-packages/Bio/pairwise2.py')
    
    During handling of the above exception, another exception occurred:
    
    Traceback (most recent call last):
      File "/opt/notebooks/final_project/.venv/lib/python3.12/site-packages/tornado/web.py", line 1790, in _execute
        result = await result
                 ^^^^^^^^^^^^
      File "/opt/notebooks/final_project/.venv/lib/python3.12/site-packages/jupyter_server/auth/decorator.py", line 73, in inner
        return await out
               ^^^^^^^^^
      File "/opt/notebooks/final_project/.venv/lib/python3.12/site-packages/jupyter_server/services/contents/handlers.py", line 182, in get
        await self._finish_error(
      File "/opt/notebooks/final_project/.venv/lib/python3.12/site-packages/jupyter_server/services/contents/handlers.py", line 114, in _finish_error
        self.write(message)
      File "/opt/notebooks/final_project/.venv/lib/python3.12/site-packages/tornado/web.py", line 914, in write
        raise RuntimeError("Cannot write() after finish()")
    RuntimeError: Cannot write() after finish()
[W 2025-05-08 19:31:57.112 ServerApp] 404 GET /api/contents/.venv/lib/python3.12/site-packages/Bio/pairwise2.py?content=0&hash=0&1746732716942 (8143833b376641c1802f0600d788494f@85.50.127.70) 0.40ms referer=http://108.128.212.205:8888/lab/tree/Final_project.ipynb
[I 2025-05-08 19:31:57.113 ServerApp] Refusing to serve hidden file or directory '/opt/notebooks/final_project/.venv/lib/python3.12/site-packages/Bio/pairwise2.py', via 404 Error
[E 2025-05-08 19:31:57.113 ServerApp] Uncaught exception GET /api/contents/.venv/lib/python3.12/site-packages/Bio/pairwise2.py?content=0&hash=0&1746732716942 (85.50.127.70)
    HTTPServerRequest(protocol='http', host='108.128.212.205:8888', method='GET', uri='/api/contents/.venv/lib/python3.12/site-packages/Bio/pairwise2.py?content=0&hash=0&1746732716942', version='HTTP/1.1', remote_ip='85.50.127.70')
    Traceback (most recent call last):
      File "/opt/notebooks/final_project/.venv/lib/python3.12/site-packages/jupyter_server/services/contents/handlers.py", line 156, in get
        model = await ensure_async(
                ^^^^^^^^^^^^^^^^^^^
      File "/opt/notebooks/final_project/.venv/lib/python3.12/site-packages/jupyter_core/utils/__init__.py", line 198, in ensure_async
        result = await obj
                 ^^^^^^^^^
      File "/opt/notebooks/final_project/.venv/lib/python3.12/site-packages/jupyter_server/services/contents/filemanager.py", line 926, in get
        model = await self._file_model(
                ^^^^^^^^^^^^^^^^^^^^^^^
      File "/opt/notebooks/final_project/.venv/lib/python3.12/site-packages/jupyter_server/services/contents/filemanager.py", line 827, in _file_model
        model = self._base_model(path)
                ^^^^^^^^^^^^^^^^^^^^^^
      File "/opt/notebooks/final_project/.venv/lib/python3.12/site-packages/jupyter_server/services/contents/filemanager.py", line 237, in _base_model
        raise web.HTTPError(404, four_o_four)
    tornado.web.HTTPError: HTTP 404: Not Found (file or directory does not exist: '.venv/lib/python3.12/site-packages/Bio/pairwise2.py')
    
    During handling of the above exception, another exception occurred:
    
    Traceback (most recent call last):
      File "/opt/notebooks/final_project/.venv/lib/python3.12/site-packages/tornado/web.py", line 1790, in _execute
        result = await result
                 ^^^^^^^^^^^^
      File "/opt/notebooks/final_project/.venv/lib/python3.12/site-packages/jupyter_server/auth/decorator.py", line 73, in inner
        return await out
               ^^^^^^^^^
      File "/opt/notebooks/final_project/.venv/lib/python3.12/site-packages/jupyter_server/services/contents/handlers.py", line 182, in get
        await self._finish_error(
      File "/opt/notebooks/final_project/.venv/lib/python3.12/site-packages/jupyter_server/services/contents/handlers.py", line 114, in _finish_error
        self.write(message)
      File "/opt/notebooks/final_project/.venv/lib/python3.12/site-packages/tornado/web.py", line 914, in write
        raise RuntimeError("Cannot write() after finish()")
    RuntimeError: Cannot write() after finish()
[I 2025-05-08 19:32:09.958 ServerApp] Saving file at /Final_project.ipynb
[I 2025-05-08 19:34:10.146 ServerApp] Saving file at /Final_project.ipynb
[I 2025-05-08 19:40:10.329 ServerApp] Saving file at /Final_project.ipynb
[I 2025-05-08 19:40:19.454 ServerApp] Saving file at /Final_project.ipynb
[I 2025-05-08 19:44:19.630 ServerApp] Saving file at /Final_project.ipynb
[I 2025-05-08 19:46:16.344 ServerApp] Kernel interrupted: c1d42182-d42d-4f04-9f08-43dce804ac64
[W 2025-05-08 19:46:16.490 ServerApp] 404 GET /api/contents/.venv/lib/python3.12/site-packages/Bio/pairwise2.py?content=0&hash=0&1746733576317 (8143833b376641c1802f0600d788494f@85.50.127.70) 0.53ms referer=http://108.128.212.205:8888/lab/tree/Final_project.ipynb
[I 2025-05-08 19:46:16.490 ServerApp] Refusing to serve hidden file or directory '/opt/notebooks/final_project/.venv/lib/python3.12/site-packages/Bio/pairwise2.py', via 404 Error
[E 2025-05-08 19:46:16.490 ServerApp] Uncaught exception GET /api/contents/.venv/lib/python3.12/site-packages/Bio/pairwise2.py?content=0&hash=0&1746733576317 (85.50.127.70)
    HTTPServerRequest(protocol='http', host='108.128.212.205:8888', method='GET', uri='/api/contents/.venv/lib/python3.12/site-packages/Bio/pairwise2.py?content=0&hash=0&1746733576317', version='HTTP/1.1', remote_ip='85.50.127.70')
    Traceback (most recent call last):
      File "/opt/notebooks/final_project/.venv/lib/python3.12/site-packages/jupyter_server/services/contents/handlers.py", line 156, in get
        model = await ensure_async(
                ^^^^^^^^^^^^^^^^^^^
      File "/opt/notebooks/final_project/.venv/lib/python3.12/site-packages/jupyter_core/utils/__init__.py", line 198, in ensure_async
        result = await obj
                 ^^^^^^^^^
      File "/opt/notebooks/final_project/.venv/lib/python3.12/site-packages/jupyter_server/services/contents/filemanager.py", line 926, in get
        model = await self._file_model(
                ^^^^^^^^^^^^^^^^^^^^^^^
      File "/opt/notebooks/final_project/.venv/lib/python3.12/site-packages/jupyter_server/services/contents/filemanager.py", line 827, in _file_model
        model = self._base_model(path)
                ^^^^^^^^^^^^^^^^^^^^^^
      File "/opt/notebooks/final_project/.venv/lib/python3.12/site-packages/jupyter_server/services/contents/filemanager.py", line 237, in _base_model
        raise web.HTTPError(404, four_o_four)
    tornado.web.HTTPError: HTTP 404: Not Found (file or directory does not exist: '.venv/lib/python3.12/site-packages/Bio/pairwise2.py')
    
    During handling of the above exception, another exception occurred:
    
    Traceback (most recent call last):
      File "/opt/notebooks/final_project/.venv/lib/python3.12/site-packages/tornado/web.py", line 1790, in _execute
        result = await result
                 ^^^^^^^^^^^^
      File "/opt/notebooks/final_project/.venv/lib/python3.12/site-packages/jupyter_server/auth/decorator.py", line 73, in inner
        return await out
               ^^^^^^^^^
      File "/opt/notebooks/final_project/.venv/lib/python3.12/site-packages/jupyter_server/services/contents/handlers.py", line 182, in get
        await self._finish_error(
      File "/opt/notebooks/final_project/.venv/lib/python3.12/site-packages/jupyter_server/services/contents/handlers.py", line 114, in _finish_error
        self.write(message)
      File "/opt/notebooks/final_project/.venv/lib/python3.12/site-packages/tornado/web.py", line 914, in write
        raise RuntimeError("Cannot write() after finish()")
    RuntimeError: Cannot write() after finish()
[W 2025-05-08 19:46:16.491 ServerApp] 404 GET /api/contents/.venv/lib/python3.12/site-packages/Bio/pairwise2.py?content=0&hash=0&1746733576317 (8143833b376641c1802f0600d788494f@85.50.127.70) 1.66ms referer=http://108.128.212.205:8888/lab/tree/Final_project.ipynb
[I 2025-05-08 19:46:16.491 ServerApp] Refusing to serve hidden file or directory '/opt/notebooks/final_project/.venv/lib/python3.12/site-packages/Bio/pairwise2.py', via 404 Error
[E 2025-05-08 19:46:16.492 ServerApp] Uncaught exception GET /api/contents/.venv/lib/python3.12/site-packages/Bio/pairwise2.py?content=0&hash=0&1746733576317 (85.50.127.70)
    HTTPServerRequest(protocol='http', host='108.128.212.205:8888', method='GET', uri='/api/contents/.venv/lib/python3.12/site-packages/Bio/pairwise2.py?content=0&hash=0&1746733576317', version='HTTP/1.1', remote_ip='85.50.127.70')
    Traceback (most recent call last):
      File "/opt/notebooks/final_project/.venv/lib/python3.12/site-packages/jupyter_server/services/contents/handlers.py", line 156, in get
        model = await ensure_async(
                ^^^^^^^^^^^^^^^^^^^
      File "/opt/notebooks/final_project/.venv/lib/python3.12/site-packages/jupyter_core/utils/__init__.py", line 198, in ensure_async
        result = await obj
                 ^^^^^^^^^
      File "/opt/notebooks/final_project/.venv/lib/python3.12/site-packages/jupyter_server/services/contents/filemanager.py", line 926, in get
        model = await self._file_model(
                ^^^^^^^^^^^^^^^^^^^^^^^
      File "/opt/notebooks/final_project/.venv/lib/python3.12/site-packages/jupyter_server/services/contents/filemanager.py", line 827, in _file_model
        model = self._base_model(path)
                ^^^^^^^^^^^^^^^^^^^^^^
      File "/opt/notebooks/final_project/.venv/lib/python3.12/site-packages/jupyter_server/services/contents/filemanager.py", line 237, in _base_model
        raise web.HTTPError(404, four_o_four)
    tornado.web.HTTPError: HTTP 404: Not Found (file or directory does not exist: '.venv/lib/python3.12/site-packages/Bio/pairwise2.py')
    
    During handling of the above exception, another exception occurred:
    
    Traceback (most recent call last):
      File "/opt/notebooks/final_project/.venv/lib/python3.12/site-packages/tornado/web.py", line 1790, in _execute
        result = await result
                 ^^^^^^^^^^^^
      File "/opt/notebooks/final_project/.venv/lib/python3.12/site-packages/jupyter_server/auth/decorator.py", line 73, in inner
        return await out
               ^^^^^^^^^
      File "/opt/notebooks/final_project/.venv/lib/python3.12/site-packages/jupyter_server/services/contents/handlers.py", line 182, in get
        await self._finish_error(
      File "/opt/notebooks/final_project/.venv/lib/python3.12/site-packages/jupyter_server/services/contents/handlers.py", line 114, in _finish_error
        self.write(message)
      File "/opt/notebooks/final_project/.venv/lib/python3.12/site-packages/tornado/web.py", line 914, in write
        raise RuntimeError("Cannot write() after finish()")
    RuntimeError: Cannot write() after finish()
[I 2025-05-08 19:46:19.804 ServerApp] Saving file at /Final_project.ipynb
[I 2025-05-08 19:46:26.237 ServerApp] Kernel restarted: c1d42182-d42d-4f04-9f08-43dce804ac64
[I 2025-05-08 19:46:26.281 ServerApp] Starting buffering for c1d42182-d42d-4f04-9f08-43dce804ac64:c47194a1-0176-408b-b12e-fa92f6a417b4
[I 2025-05-08 19:46:26.338 ServerApp] Connecting to kernel c1d42182-d42d-4f04-9f08-43dce804ac64.
[I 2025-05-08 19:46:26.338 ServerApp] Restoring connection for c1d42182-d42d-4f04-9f08-43dce804ac64:c47194a1-0176-408b-b12e-fa92f6a417b4
[I 2025-05-08 19:46:28.381 ServerApp] Saving file at /Final_project.ipynb
[W 2025-05-08 19:47:44.138 ServerApp] 404 GET /api/contents/.venv/lib/python3.12/site-packages/Bio/pairwise2.py?content=0&hash=0&1746733663974 (8143833b376641c1802f0600d788494f@85.50.127.70) 0.50ms referer=http://108.128.212.205:8888/lab/tree/Final_project.ipynb
[I 2025-05-08 19:47:44.138 ServerApp] Refusing to serve hidden file or directory '/opt/notebooks/final_project/.venv/lib/python3.12/site-packages/Bio/pairwise2.py', via 404 Error
[E 2025-05-08 19:47:44.138 ServerApp] Uncaught exception GET /api/contents/.venv/lib/python3.12/site-packages/Bio/pairwise2.py?content=0&hash=0&1746733663974 (85.50.127.70)
    HTTPServerRequest(protocol='http', host='108.128.212.205:8888', method='GET', uri='/api/contents/.venv/lib/python3.12/site-packages/Bio/pairwise2.py?content=0&hash=0&1746733663974', version='HTTP/1.1', remote_ip='85.50.127.70')
    Traceback (most recent call last):
      File "/opt/notebooks/final_project/.venv/lib/python3.12/site-packages/jupyter_server/services/contents/handlers.py", line 156, in get
        model = await ensure_async(
                ^^^^^^^^^^^^^^^^^^^
      File "/opt/notebooks/final_project/.venv/lib/python3.12/site-packages/jupyter_core/utils/__init__.py", line 198, in ensure_async
        result = await obj
                 ^^^^^^^^^
      File "/opt/notebooks/final_project/.venv/lib/python3.12/site-packages/jupyter_server/services/contents/filemanager.py", line 926, in get
        model = await self._file_model(
                ^^^^^^^^^^^^^^^^^^^^^^^
      File "/opt/notebooks/final_project/.venv/lib/python3.12/site-packages/jupyter_server/services/contents/filemanager.py", line 827, in _file_model
        model = self._base_model(path)
                ^^^^^^^^^^^^^^^^^^^^^^
      File "/opt/notebooks/final_project/.venv/lib/python3.12/site-packages/jupyter_server/services/contents/filemanager.py", line 237, in _base_model
        raise web.HTTPError(404, four_o_four)
    tornado.web.HTTPError: HTTP 404: Not Found (file or directory does not exist: '.venv/lib/python3.12/site-packages/Bio/pairwise2.py')
    
    During handling of the above exception, another exception occurred:
    
    Traceback (most recent call last):
      File "/opt/notebooks/final_project/.venv/lib/python3.12/site-packages/tornado/web.py", line 1790, in _execute
        result = await result
                 ^^^^^^^^^^^^
      File "/opt/notebooks/final_project/.venv/lib/python3.12/site-packages/jupyter_server/auth/decorator.py", line 73, in inner
        return await out
               ^^^^^^^^^
      File "/opt/notebooks/final_project/.venv/lib/python3.12/site-packages/jupyter_server/services/contents/handlers.py", line 182, in get
        await self._finish_error(
      File "/opt/notebooks/final_project/.venv/lib/python3.12/site-packages/jupyter_server/services/contents/handlers.py", line 114, in _finish_error
        self.write(message)
      File "/opt/notebooks/final_project/.venv/lib/python3.12/site-packages/tornado/web.py", line 914, in write
        raise RuntimeError("Cannot write() after finish()")
    RuntimeError: Cannot write() after finish()
[I 2025-05-08 19:48:28.551 ServerApp] Saving file at /Final_project.ipynb
[I 2025-05-08 19:50:19.535 ServerApp] Kernel interrupted: c1d42182-d42d-4f04-9f08-43dce804ac64
[W 2025-05-08 19:50:19.684 ServerApp] 404 GET /api/contents/.venv/lib/python3.12/site-packages/Bio/pairwise2.py?content=0&hash=0&1746733819532 (8143833b376641c1802f0600d788494f@85.50.127.70) 0.62ms referer=http://108.128.212.205:8888/lab/tree/Final_project.ipynb
[I 2025-05-08 19:50:19.684 ServerApp] Refusing to serve hidden file or directory '/opt/notebooks/final_project/.venv/lib/python3.12/site-packages/Bio/pairwise2.py', via 404 Error
[E 2025-05-08 19:50:19.684 ServerApp] Uncaught exception GET /api/contents/.venv/lib/python3.12/site-packages/Bio/pairwise2.py?content=0&hash=0&1746733819532 (85.50.127.70)
    HTTPServerRequest(protocol='http', host='108.128.212.205:8888', method='GET', uri='/api/contents/.venv/lib/python3.12/site-packages/Bio/pairwise2.py?content=0&hash=0&1746733819532', version='HTTP/1.1', remote_ip='85.50.127.70')
    Traceback (most recent call last):
      File "/opt/notebooks/final_project/.venv/lib/python3.12/site-packages/jupyter_server/services/contents/handlers.py", line 156, in get
        model = await ensure_async(
                ^^^^^^^^^^^^^^^^^^^
      File "/opt/notebooks/final_project/.venv/lib/python3.12/site-packages/jupyter_core/utils/__init__.py", line 198, in ensure_async
        result = await obj
                 ^^^^^^^^^
      File "/opt/notebooks/final_project/.venv/lib/python3.12/site-packages/jupyter_server/services/contents/filemanager.py", line 926, in get
        model = await self._file_model(
                ^^^^^^^^^^^^^^^^^^^^^^^
      File "/opt/notebooks/final_project/.venv/lib/python3.12/site-packages/jupyter_server/services/contents/filemanager.py", line 827, in _file_model
        model = self._base_model(path)
                ^^^^^^^^^^^^^^^^^^^^^^
      File "/opt/notebooks/final_project/.venv/lib/python3.12/site-packages/jupyter_server/services/contents/filemanager.py", line 237, in _base_model
        raise web.HTTPError(404, four_o_four)
    tornado.web.HTTPError: HTTP 404: Not Found (file or directory does not exist: '.venv/lib/python3.12/site-packages/Bio/pairwise2.py')
    
    During handling of the above exception, another exception occurred:
    
    Traceback (most recent call last):
      File "/opt/notebooks/final_project/.venv/lib/python3.12/site-packages/tornado/web.py", line 1790, in _execute
        result = await result
                 ^^^^^^^^^^^^
      File "/opt/notebooks/final_project/.venv/lib/python3.12/site-packages/jupyter_server/auth/decorator.py", line 73, in inner
        return await out
               ^^^^^^^^^
      File "/opt/notebooks/final_project/.venv/lib/python3.12/site-packages/jupyter_server/services/contents/handlers.py", line 182, in get
        await self._finish_error(
      File "/opt/notebooks/final_project/.venv/lib/python3.12/site-packages/jupyter_server/services/contents/handlers.py", line 114, in _finish_error
        self.write(message)
      File "/opt/notebooks/final_project/.venv/lib/python3.12/site-packages/tornado/web.py", line 914, in write
        raise RuntimeError("Cannot write() after finish()")
    RuntimeError: Cannot write() after finish()
[W 2025-05-08 19:50:19.685 ServerApp] 404 GET /api/contents/.venv/lib/python3.12/site-packages/Bio/pairwise2.py?content=0&hash=0&1746733819533 (8143833b376641c1802f0600d788494f@85.50.127.70) 0.35ms referer=http://108.128.212.205:8888/lab/tree/Final_project.ipynb
[I 2025-05-08 19:50:19.685 ServerApp] Refusing to serve hidden file or directory '/opt/notebooks/final_project/.venv/lib/python3.12/site-packages/Bio/pairwise2.py', via 404 Error
[E 2025-05-08 19:50:19.685 ServerApp] Uncaught exception GET /api/contents/.venv/lib/python3.12/site-packages/Bio/pairwise2.py?content=0&hash=0&1746733819533 (85.50.127.70)
    HTTPServerRequest(protocol='http', host='108.128.212.205:8888', method='GET', uri='/api/contents/.venv/lib/python3.12/site-packages/Bio/pairwise2.py?content=0&hash=0&1746733819533', version='HTTP/1.1', remote_ip='85.50.127.70')
    Traceback (most recent call last):
      File "/opt/notebooks/final_project/.venv/lib/python3.12/site-packages/jupyter_server/services/contents/handlers.py", line 156, in get
        model = await ensure_async(
                ^^^^^^^^^^^^^^^^^^^
      File "/opt/notebooks/final_project/.venv/lib/python3.12/site-packages/jupyter_core/utils/__init__.py", line 198, in ensure_async
        result = await obj
                 ^^^^^^^^^
      File "/opt/notebooks/final_project/.venv/lib/python3.12/site-packages/jupyter_server/services/contents/filemanager.py", line 926, in get
        model = await self._file_model(
                ^^^^^^^^^^^^^^^^^^^^^^^
      File "/opt/notebooks/final_project/.venv/lib/python3.12/site-packages/jupyter_server/services/contents/filemanager.py", line 827, in _file_model
        model = self._base_model(path)
                ^^^^^^^^^^^^^^^^^^^^^^
      File "/opt/notebooks/final_project/.venv/lib/python3.12/site-packages/jupyter_server/services/contents/filemanager.py", line 237, in _base_model
        raise web.HTTPError(404, four_o_four)
    tornado.web.HTTPError: HTTP 404: Not Found (file or directory does not exist: '.venv/lib/python3.12/site-packages/Bio/pairwise2.py')
    
    During handling of the above exception, another exception occurred:
    
    Traceback (most recent call last):
      File "/opt/notebooks/final_project/.venv/lib/python3.12/site-packages/tornado/web.py", line 1790, in _execute
        result = await result
                 ^^^^^^^^^^^^
      File "/opt/notebooks/final_project/.venv/lib/python3.12/site-packages/jupyter_server/auth/decorator.py", line 73, in inner
        return await out
               ^^^^^^^^^
      File "/opt/notebooks/final_project/.venv/lib/python3.12/site-packages/jupyter_server/services/contents/handlers.py", line 182, in get
        await self._finish_error(
      File "/opt/notebooks/final_project/.venv/lib/python3.12/site-packages/jupyter_server/services/contents/handlers.py", line 114, in _finish_error
        self.write(message)
      File "/opt/notebooks/final_project/.venv/lib/python3.12/site-packages/tornado/web.py", line 914, in write
        raise RuntimeError("Cannot write() after finish()")
    RuntimeError: Cannot write() after finish()
[I 2025-05-08 19:50:29.515 ServerApp] Saving file at /Final_project.ipynb
[I 2025-05-08 19:52:30.478 ServerApp] Saving file at /Final_project.ipynb
[I 2025-05-08 19:54:30.660 ServerApp] Saving file at /Final_project.ipynb
[I 2025-05-08 19:56:30.841 ServerApp] Saving file at /Final_project.ipynb
[I 2025-05-08 19:57:44.892 ServerApp] Saving file at /Final_project.ipynb
[I 2025-05-08 19:57:48.307 ServerApp] Saving file at /Final_project.ipynb
[I 2025-05-08 19:59:45.072 ServerApp] Saving file at /Final_project.ipynb
[I 2025-05-08 20:01:45.244 ServerApp] Saving file at /Final_project.ipynb
[I 2025-05-08 20:02:14.209 ServerApp] Kernel interrupted: c1d42182-d42d-4f04-9f08-43dce804ac64
[W 2025-05-08 20:02:14.321 ServerApp] 404 GET /api/contents/.venv/lib/python3.12/site-packages/Bio/pairwise2.py?content=0&hash=0&1746734534181 (8143833b376641c1802f0600d788494f@85.50.127.70) 0.76ms referer=http://108.128.212.205:8888/lab/tree/Final_project.ipynb
[I 2025-05-08 20:02:14.321 ServerApp] Refusing to serve hidden file or directory '/opt/notebooks/final_project/.venv/lib/python3.12/site-packages/Bio/pairwise2.py', via 404 Error
[E 2025-05-08 20:02:14.321 ServerApp] Uncaught exception GET /api/contents/.venv/lib/python3.12/site-packages/Bio/pairwise2.py?content=0&hash=0&1746734534181 (85.50.127.70)
    HTTPServerRequest(protocol='http', host='108.128.212.205:8888', method='GET', uri='/api/contents/.venv/lib/python3.12/site-packages/Bio/pairwise2.py?content=0&hash=0&1746734534181', version='HTTP/1.1', remote_ip='85.50.127.70')
    Traceback (most recent call last):
      File "/opt/notebooks/final_project/.venv/lib/python3.12/site-packages/jupyter_server/services/contents/handlers.py", line 156, in get
        model = await ensure_async(
                ^^^^^^^^^^^^^^^^^^^
      File "/opt/notebooks/final_project/.venv/lib/python3.12/site-packages/jupyter_core/utils/__init__.py", line 198, in ensure_async
        result = await obj
                 ^^^^^^^^^
      File "/opt/notebooks/final_project/.venv/lib/python3.12/site-packages/jupyter_server/services/contents/filemanager.py", line 926, in get
        model = await self._file_model(
                ^^^^^^^^^^^^^^^^^^^^^^^
      File "/opt/notebooks/final_project/.venv/lib/python3.12/site-packages/jupyter_server/services/contents/filemanager.py", line 827, in _file_model
        model = self._base_model(path)
                ^^^^^^^^^^^^^^^^^^^^^^
      File "/opt/notebooks/final_project/.venv/lib/python3.12/site-packages/jupyter_server/services/contents/filemanager.py", line 237, in _base_model
        raise web.HTTPError(404, four_o_four)
    tornado.web.HTTPError: HTTP 404: Not Found (file or directory does not exist: '.venv/lib/python3.12/site-packages/Bio/pairwise2.py')
    
    During handling of the above exception, another exception occurred:
    
    Traceback (most recent call last):
      File "/opt/notebooks/final_project/.venv/lib/python3.12/site-packages/tornado/web.py", line 1790, in _execute
        result = await result
                 ^^^^^^^^^^^^
      File "/opt/notebooks/final_project/.venv/lib/python3.12/site-packages/jupyter_server/auth/decorator.py", line 73, in inner
        return await out
               ^^^^^^^^^
      File "/opt/notebooks/final_project/.venv/lib/python3.12/site-packages/jupyter_server/services/contents/handlers.py", line 182, in get
        await self._finish_error(
      File "/opt/notebooks/final_project/.venv/lib/python3.12/site-packages/jupyter_server/services/contents/handlers.py", line 114, in _finish_error
        self.write(message)
      File "/opt/notebooks/final_project/.venv/lib/python3.12/site-packages/tornado/web.py", line 914, in write
        raise RuntimeError("Cannot write() after finish()")
    RuntimeError: Cannot write() after finish()
[W 2025-05-08 20:02:14.322 ServerApp] 404 GET /api/contents/.venv/lib/python3.12/site-packages/Bio/pairwise2.py?content=0&hash=0&1746734534181 (8143833b376641c1802f0600d788494f@85.50.127.70) 0.35ms referer=http://108.128.212.205:8888/lab/tree/Final_project.ipynb
[I 2025-05-08 20:02:14.322 ServerApp] Refusing to serve hidden file or directory '/opt/notebooks/final_project/.venv/lib/python3.12/site-packages/Bio/pairwise2.py', via 404 Error
[E 2025-05-08 20:02:14.322 ServerApp] Uncaught exception GET /api/contents/.venv/lib/python3.12/site-packages/Bio/pairwise2.py?content=0&hash=0&1746734534181 (85.50.127.70)
    HTTPServerRequest(protocol='http', host='108.128.212.205:8888', method='GET', uri='/api/contents/.venv/lib/python3.12/site-packages/Bio/pairwise2.py?content=0&hash=0&1746734534181', version='HTTP/1.1', remote_ip='85.50.127.70')
    Traceback (most recent call last):
      File "/opt/notebooks/final_project/.venv/lib/python3.12/site-packages/jupyter_server/services/contents/handlers.py", line 156, in get
        model = await ensure_async(
                ^^^^^^^^^^^^^^^^^^^
      File "/opt/notebooks/final_project/.venv/lib/python3.12/site-packages/jupyter_core/utils/__init__.py", line 198, in ensure_async
        result = await obj
                 ^^^^^^^^^
      File "/opt/notebooks/final_project/.venv/lib/python3.12/site-packages/jupyter_server/services/contents/filemanager.py", line 926, in get
        model = await self._file_model(
                ^^^^^^^^^^^^^^^^^^^^^^^
      File "/opt/notebooks/final_project/.venv/lib/python3.12/site-packages/jupyter_server/services/contents/filemanager.py", line 827, in _file_model
        model = self._base_model(path)
                ^^^^^^^^^^^^^^^^^^^^^^
      File "/opt/notebooks/final_project/.venv/lib/python3.12/site-packages/jupyter_server/services/contents/filemanager.py", line 237, in _base_model
        raise web.HTTPError(404, four_o_four)
    tornado.web.HTTPError: HTTP 404: Not Found (file or directory does not exist: '.venv/lib/python3.12/site-packages/Bio/pairwise2.py')
    
    During handling of the above exception, another exception occurred:
    
    Traceback (most recent call last):
      File "/opt/notebooks/final_project/.venv/lib/python3.12/site-packages/tornado/web.py", line 1790, in _execute
        result = await result
                 ^^^^^^^^^^^^
      File "/opt/notebooks/final_project/.venv/lib/python3.12/site-packages/jupyter_server/auth/decorator.py", line 73, in inner
        return await out
               ^^^^^^^^^
      File "/opt/notebooks/final_project/.venv/lib/python3.12/site-packages/jupyter_server/services/contents/handlers.py", line 182, in get
        await self._finish_error(
      File "/opt/notebooks/final_project/.venv/lib/python3.12/site-packages/jupyter_server/services/contents/handlers.py", line 114, in _finish_error
        self.write(message)
      File "/opt/notebooks/final_project/.venv/lib/python3.12/site-packages/tornado/web.py", line 914, in write
        raise RuntimeError("Cannot write() after finish()")
    RuntimeError: Cannot write() after finish()
[I 2025-05-08 20:03:45.416 ServerApp] Saving file at /Final_project.ipynb
[I 2025-05-08 20:06:47.377 ServerApp] Saving file at /Final_project.ipynb
[I 2025-05-08 20:06:55.928 ServerApp] Kernel interrupted: c1d42182-d42d-4f04-9f08-43dce804ac64
[I 2025-05-08 20:06:57.482 ServerApp] Starting buffering for c1d42182-d42d-4f04-9f08-43dce804ac64:c47194a1-0176-408b-b12e-fa92f6a417b4
[C 2025-05-08 20:07:39.850 ServerApp] received signal 15, stopping
[I 2025-05-08 20:07:39.850 ServerApp] Shutting down 5 extensions
[I 2025-05-08 20:07:39.851 ServerApp] Shutting down 1 kernel
[I 2025-05-08 20:07:39.851 ServerApp] Kernel shutdown: c1d42182-d42d-4f04-9f08-43dce804ac64
[I 2025-05-08 20:09:08.978 ServerApp] jupyter_lsp | extension was successfully linked.
[I 2025-05-08 20:09:08.981 ServerApp] jupyter_server_terminals | extension was successfully linked.
[I 2025-05-08 20:09:08.984 ServerApp] jupyterlab | extension was successfully linked.
[I 2025-05-08 20:09:09.143 ServerApp] notebook_shim | extension was successfully linked.
[I 2025-05-08 20:09:09.155 ServerApp] notebook_shim | extension was successfully loaded.
[I 2025-05-08 20:09:09.156 ServerApp] jupyter_lsp | extension was successfully loaded.
[I 2025-05-08 20:09:09.157 ServerApp] jupyter_server_terminals | extension was successfully loaded.
[I 2025-05-08 20:09:09.159 LabApp] JupyterLab extension loaded from /opt/notebooks/final_project/.venv/lib/python3.12/site-packages/jupyterlab
[I 2025-05-08 20:09:09.159 LabApp] JupyterLab application directory is /opt/notebooks/final_project/.venv/share/jupyter/lab
[I 2025-05-08 20:09:09.159 LabApp] Extension Manager is 'pypi'.
[I 2025-05-08 20:09:09.196 ServerApp] jupyterlab | extension was successfully loaded.
[I 2025-05-08 20:09:09.197 ServerApp] Serving notebooks from local directory: /opt/notebooks/final_project
[I 2025-05-08 20:09:09.197 ServerApp] Jupyter Server 2.15.0 is running at:
[I 2025-05-08 20:09:09.197 ServerApp] http://localhost:8888/lab
[I 2025-05-08 20:09:09.197 ServerApp]     http://127.0.0.1:8888/lab
[I 2025-05-08 20:09:09.197 ServerApp] Use Control-C to stop this server and shut down all kernels (twice to skip confirmation).
[I 2025-05-08 20:09:09.211 ServerApp] Skipped non-installed server(s): bash-language-server, dockerfile-language-server-nodejs, javascript-typescript-langserver, jedi-language-server, julia-language-server, pyright, python-language-server, python-lsp-server, r-languageserver, sql-language-server, texlab, typescript-language-server, unified-language-server, vscode-css-languageserver-bin, vscode-html-languageserver-bin, vscode-json-languageserver-bin, yaml-language-server
[I 2025-05-08 20:09:39.980 ServerApp] Interrupted...
[I 2025-05-08 20:10:20.697 ServerApp] jupyter_lsp | extension was successfully linked.
[I 2025-05-08 20:10:20.700 ServerApp] jupyter_server_terminals | extension was successfully linked.
[I 2025-05-08 20:10:20.703 ServerApp] jupyterlab | extension was successfully linked.
[I 2025-05-08 20:10:20.861 ServerApp] notebook_shim | extension was successfully linked.
[I 2025-05-08 20:10:20.873 ServerApp] notebook_shim | extension was successfully loaded.
[I 2025-05-08 20:10:20.875 ServerApp] jupyter_lsp | extension was successfully loaded.
[I 2025-05-08 20:10:20.875 ServerApp] jupyter_server_terminals | extension was successfully loaded.
[I 2025-05-08 20:10:20.877 LabApp] JupyterLab extension loaded from /opt/notebooks/final_project/.venv/lib/python3.12/site-packages/jupyterlab
[I 2025-05-08 20:10:20.877 LabApp] JupyterLab application directory is /opt/notebooks/final_project/.venv/share/jupyter/lab
[I 2025-05-08 20:10:20.877 LabApp] Extension Manager is 'pypi'.
[I 2025-05-08 20:10:20.915 ServerApp] jupyterlab | extension was successfully loaded.
[I 2025-05-08 20:10:20.915 ServerApp] Serving notebooks from local directory: /opt/notebooks/final_project
[I 2025-05-08 20:10:20.915 ServerApp] Jupyter Server 2.15.0 is running at:
[I 2025-05-08 20:10:20.915 ServerApp] http://localhost:8888/lab
[I 2025-05-08 20:10:20.915 ServerApp]     http://127.0.0.1:8888/lab
[I 2025-05-08 20:10:20.915 ServerApp] Use Control-C to stop this server and shut down all kernels (twice to skip confirmation).
[I 2025-05-08 20:10:20.930 ServerApp] Skipped non-installed server(s): bash-language-server, dockerfile-language-server-nodejs, javascript-typescript-langserver, jedi-language-server, julia-language-server, pyright, python-language-server, python-lsp-server, r-languageserver, sql-language-server, texlab, typescript-language-server, unified-language-server, vscode-css-languageserver-bin, vscode-html-languageserver-bin, vscode-json-languageserver-bin, yaml-language-server
[I 2025-05-08 20:12:52.072 ServerApp] Interrupted...
